<?xml version="1.0" ?>
<!-- =================================================================================== -->
<!-- |    This document was autogenerated by xacro from /tmp/tmpArm.xml                | -->
<!-- |    EDITING THIS FILE BY HAND IS NOT RECOMMENDED                                 | -->
<!-- =================================================================================== -->
<!-- <?xml version="1.0"> -->
<!-- Manipulator -->
<robot name="parametric_arm">
   <link name="base">
      <inertial>
         <origin rpy="0 0 0" xyz="0 0 0"/>
         <mass value="0.5"/>
         <inertia ixx="1.6E-04" ixy="0" ixz="0" iyy="1.1E-04" iyz="0" izz="6.5E-05"/>
      </inertial>
      <visual>
         <origin rpy="0 0 0" xyz="0 0 0"/>
         <geometry>
            <box size="0.05 0.05 0.01"/>
         </geometry>
         <material name="blue">
            <color rgba="0.369 0.506 0.674 1"/>
         </material>
      </visual>
      <collision>
         <origin rpy="0 0 0" xyz="0 0 0"/>
         <geometry>
            <box size="0.05 0.05 0.1"/>
         </geometry>
      </collision>
   </link>
   <joint name="RZ_base" type="revolute">
      <origin rpy="0 0 0" xyz="0 0 0"/>
      <parent link="base"/>
      <child link="base_link"/>
      <axis xyz="0 0 1"/>
      <limit effort="12" velocity="38.2"/>
   </joint>
   <link name="base_link">
      <inertial>
         <origin rpy="0 0 0" xyz="0 0 0"/>
         <mass value="0.5"/>
         <inertia ixx="5E-04" ixy="0" ixz="0" iyy="3E-04" iyz="0" izz="3E-04"/>
      </inertial>
      <visual>
         <origin rpy="0 0 0" xyz="0 0 0"/>
         <geometry>
            <box size="0.5 0.5 0.01"/>
         </geometry>
         <material name="blue">
            <color rgba="0.369 0.506 0.674 1"/>
         </material>
      </visual>
      <collision>
         <origin rpy="0 0 0" xyz="0 0 0"/>
         <geometry>
            <box size="0.5 0.5 0.01"/>
         </geometry>
      </collision>
   </link>
   <joint name="RY_0" type="revolute">
      <origin rpy="0 0 0" xyz="0 0 0"/>
      <parent link="base_link"/>
      <child link="link_0"/>
      <axis xyz="0 1 0"/>
      <limit effort="12" velocity="38.2"/>
   </joint>
   <link name="link_0">
      <inertial>
         <origin rpy="0 0 0" xyz="0 0 -0.804669182706579"/>
         <mass value="1.2"/>
         <inertia ixx="0.0007042" ixy="0" ixz="0" iyy="0.0010807" iyz="0" izz="0.0015899"/>
      </inertial>
      <!-- <xacro:box_visual size="0.01 0.01 ${link_0}"/> -->
      <visual>
         <origin rpy="0 0 0" xyz="0 0 -0.804669182706579"/>
         <geometry>
            <box size="0.05 0.05 1.609338365413158"/>
         </geometry>
         <material name="red">
            <color rgba="0.749 0.380 0.410 1"/>
         </material>
      </visual>
      <collision>
         <origin rpy="0 0 0" xyz="0 0 -0.804669182706579"/>
         <geometry>
            <box size="0.05 0.05 1.609338365413158"/>
         </geometry>
      </collision>
   </link>
   <link name="link_1">
      <inertial>
         <origin rpy="0 0 0" xyz="0 0 -0.8026449122903752"/>
         <mass value="0.13037"/>
         <inertia ixx="1.972E-05" ixy="0" ixz="0" iyy="6.3038E-05" iyz="0" izz="6.3388E-05"/>
      </inertial>
      <visual>
         <origin rpy="0 0 0" xyz="0 0 -0.8026449122903752"/>
         <geometry>
            <box size="0.05 0.05 1.6052898245807503"/>
         </geometry>
         <material name="orange">
            <color rgba="0.815 0.529 0.439 1"/>
         </material>
      </visual>
      <collision>
         <origin rpy="0 0 0" xyz="0 0 -0.8026449122903752"/>
         <geometry>
            <box size="0.05 0.05 1.6052898245807503"/>
         </geometry>
      </collision>
   </link>
   <joint name="RY_1" type="revolute">
      <origin rpy="0 0 0" xyz="0 0 -1.609338365413158"/>
      <parent link="link_0"/>
      <child link="link_1"/>
      <axis xyz="0 1 0"/>
      <limit effort="12" velocity="38.2"/>
   </joint>
   <joint name="arm_fixed_joint" type="fixed">
      <origin rpy="0 0 0" xyz="0 0 -1.6052898245807503"/>
      <parent link="link_1"/>
      <child link="gripper"/>
   </joint>
   <link name="gripper">
      <inertial>
         <origin rpy="0 0.0 0" xyz="0 0 0"/>
         <mass value="0.01"/>
         <inertia ixx="0.00000057" ixy="0.0" ixz="0.0" iyy="0.00000084" iyz="0.0" izz="0.00000053"/>
      </inertial>
      <visual>
         <geometry>
            <sphere radius="0.05"/>
         </geometry>
         <material name="blue">
            <color rgba="0.369 0.506 0.674 1"/>
         </material>
      </visual>
   </link>
</robot>
obot>
