<?xml version="1.0" ?>
<!-- =================================================================================== -->
<!-- |    This document was autogenerated by xacro from /tmp/tmpMonoped.xml            | -->
<!-- |    EDITING THIS FILE BY HAND IS NOT RECOMMENDED                                 | -->
<!-- =================================================================================== -->
<!-- <?xml version="1.0"> -->
<!-- Manipulator -->
<robot name="hopperDFKI">
   <link name="slider">
      <inertial>
         <origin rpy="0 0 0" xyz="0 0 0"/>
         <mass value="0.5"/>
         <inertia ixx="1.6E-04" ixy="0" ixz="0" iyy="1.1E-04" iyz="0" izz="6.5E-05"/>
      </inertial>
      <visual>
         <origin rpy="0 0 0" xyz="0 0 0"/>
         <geometry>
            <box size="0.05 0.05 0.1"/>
         </geometry>
         <material name="blue">
            <color rgba="0.369 0.506 0.674 1"/>
         </material>
      </visual>
      <collision>
         <origin rpy="0 0 0" xyz="0 0 0"/>
         <geometry>
            <box size="0.05 0.05 0.1"/>
         </geometry>
      </collision>
   </link>
   <joint name="connector_joint" type="fixed">
      <origin rpy="0 0 0" xyz="0 0 0"/>
      <parent link="slider"/>
      <child link="hip"/>
      <axis xyz="0 0 0"/>
   </joint>
   <link name="hip">
      <inertial>
         <origin rpy="0 0 0" xyz="0 0 0"/>
         <mass value="0.5"/>
         <inertia ixx="5E-04" ixy="0" ixz="0" iyy="3E-04" iyz="0" izz="3E-04"/>
      </inertial>
      <visual>
         <origin rpy="0 0 0" xyz="0 0 0"/>
         <geometry>
            <box size="0.01 0.01 0.1"/>
         </geometry>
         <material name="blue">
            <color rgba="0.369 0.506 0.674 1"/>
         </material>
      </visual>
      <collision>
         <origin rpy="0 0 0" xyz="0 0 0"/>
         <geometry>
            <box size="0.01 0.01 0.1"/>
         </geometry>
      </collision>
   </link>
   <joint name="hip_joint" type="revolute">
      <origin rpy="0 0 0" xyz="0 0 -0.05"/>
      <parent link="hip"/>
      <child link="link_0"/>
      <axis xyz="0 1 0"/>
      <limit effort="12" velocity="38.2"/>
   </joint>
   <link name="link_0">
      <inertial>
         <origin rpy="0 0 0" xyz="0 0 -0.05"/>
         <mass value="1.2"/>
         <inertia ixx="0.0007042" ixy="0" ixz="0" iyy="0.0010807" iyz="0" izz="0.0015899"/>
      </inertial>
      <!-- <xacro:box_visual size="0.01 0.01 ${link_0}"/> -->
      <visual>
         <origin rpy="0 0 0" xyz="0 0 -0.05"/>
         <geometry>
            <box size="0.01 0.01 0.1"/>
         </geometry>
         <material name="green">
            <color rgba="0.639 0.745 0.549 1"/>
         </material>
      </visual>
      <collision>
         <origin rpy="0 0 0" xyz="0 0 -0.05"/>
         <geometry>
            <box size="0.01 0.01 0.1"/>
         </geometry>
      </collision>
   </link>
   <link name="link_1">
      <inertial>
         <origin rpy="0 0 0" xyz="0 0 -0.25"/>
         <mass value="0.13037"/>
         <inertia ixx="1.972E-05" ixy="0" ixz="0" iyy="6.3038E-05" iyz="0" izz="6.3388E-05"/>
      </inertial>
      <visual>
         <origin rpy="0 0 0" xyz="0 0 -0.25"/>
         <geometry>
            <box size="0.01 0.01 0.5"/>
         </geometry>
         <material name="blue">
            <color rgba="0.369 0.506 0.674 1"/>
         </material>
      </visual>
      <collision>
         <origin rpy="0 0 0" xyz="0 0 -0.25"/>
         <geometry>
            <box size="0.01 0.01 0.5"/>
         </geometry>
      </collision>
   </link>
   <joint name="knee_joint" type="revolute">
      <origin rpy="0 0 0" xyz="0 0 -0.1"/>
      <parent link="link_0"/>
      <child link="link_1"/>
      <axis xyz="0 1 0"/>
      <limit effort="12" velocity="38.2"/>
   </joint>
   <joint name="foot_fixed_joint" type="fixed">
      <origin rpy="0 0 0" xyz="0 0 -0.5"/>
      <parent link="link_1"/>
      <child link="foot"/>
   </joint>
   <link name="foot">
      <inertial>
         <origin rpy="0 0.0 0" xyz="0 0 0"/>
         <mass value="0.01"/>
         <inertia ixx="0.00000057" ixy="0.0" ixz="0.0" iyy="0.00000084" iyz="0.0" izz="0.00000053"/>
      </inertial>
      <visual>
         <geometry>
            <sphere radius="0.02"/>
         </geometry>
         <material name="black">
            <color rgba="0.263 0.298 0.369 1"/>
         </material>
      </visual>
   </link>
</robot>
